Workbook

Sheet Summ
A1: name | B1: exp_group | C1: s_30 | D1: s_60 | E1: s_90 | F1: s_120 | G1: success_30 | H1: number_30 | I1: var_throw | J1: var_hold | K1: res_1_ces | L1: res_2_ces | M1: res_3_ces | N1: note_ces | O1: effic_ces | P1: res_1_sum | Q1: res_2_sum | R1: res_3_sum | S1: note_sum | T1: effic_sum | U1: res_1_ipp | V1: res_2_ipp | W1: res_3_ipp | X1: note_ipp | Y1: effic_ipp
A2: Арутюнян | B2: 1 | C2: 10 | D2: 10 | E2: 9 | F2: 9 | G2: 4 | H2: 5 | I2: 8 | J2: 7 | K2: 4 | L2: 1.9 | M2: 2.3 | N2: 5 | O2: 2.6315789 | P2: 2.1 | Q2: 2.2 | R2: 2.3 | S2: 5 | T2: 2.3809524 | U2: 1.25 | V2: 1.45 | W2: 2.5 | X2: 5 | Y2: 4
A3: Корчагина | B3: 1 | C3: 9 | D3: 8 | E3: 9 | F3: 9 | G3: 2 | H3: 4 | I3: 9 | J3: 5 | K3: 2.6 | L3: 2 | M3: 1.9 | N3: 5 | O3: 2.6315789 | P3: 2.2 | Q3: 2.3 | R3: 2.8 | S3: 5 | T3: 2.2727273 | U3: 1.45 | V3: 1.5 | W3: 2.1 | X3: 5 | Y3: 3.4482759
A4: Закоптелкова | B4: 1 | C4: 7 | D4: 5 | E4: 6 | F4: 5 | G4: 2 | H4: 7 | I4: 7 | J4: 4 | K4: 2.3 | L4: 3.2 | M4: 1.9 | N4: 5 | O4: 2.6315789 | P4: 3.4 | Q4: 2.5 | R4: 3.5 | S4: 4 | T4: 1.6 | U4: 1.8 | V4: 1.9 | W4: 2.9 | X4: 3 | Y4: 1.6666667
A5: Голубинская | B5: 1 | C5: 4 | D5: 2 | E5: 2 | F5: 3 | G5: 1 | H5: 9 | I5: 6 | J5: 4 | L5: 5.5 | M5: 3 | N5: 2 | O5: 0.66666667 | Q5: 4 | S5: 2 | T5: 0.5 | U5: 4.3 | V5: 3.2 | X5: 2 | Y5: 0.625
A6: Алиев | B6: 1 | C6: 9 | D6: 6 | E6: 6 | F6: 6 | G6: 3 | H6: 6 | I6: 9 | J6: 5 | K6: 2.3 | L6: 2.5 | M6: 3.2 | N6: 4 | O6: 1.7391304 | P6: 4.1 | Q6: 4 | R6: 3.1 | S6: 4 | T6: 1.2903226 | U6: 1.7 | V6: 2.3 | W6: 2.1 | X6: 4 | Y6: 2.3529412
A7: Устинов | B7: 1 | C7: 6 | D7: 5 | E7: 4 | F7: 3 | G7: 1 | H7: 6 | I7: 8 | J7: 5 | K7: 4.3 | L7: 3 | M7: 2.5 | N7: 2 | O7: 0.8 | P7: 4 | Q7: 2.3 | R7: 3.7 | S7: 4 | T7: 1.7391304 | U7: 2.25 | V7: 3 | X7: 3 | Y7: 1.3333333
A8: Закоптелков | B8: 1 | C8: 8 | D8: 6 | E8: 6 | F8: 4 | G8: 5 | H8: 11 | I8: 6 | J8: 6 | K8: 2.3 | L8: 2.5 | M8: 2.3 | N8: 3 | O8: 1.3043478 | Q8: 4.5 | R8: 3.9 | S8: 3 | T8: 0.76923077 | U8: 1.9 | V8: 2 | W8: 2 | X8: 3 | Y8: 1.5789474
A9: Ефремов | B9: 1 | C9: 7 | D9: 6 | E9: 5 | F9: 4 | G9: 2 | H9: 10 | I9: 6 | J9: 4 | K9: 2 | L9: 2.2 | M9: 2.3 | N9: 4 | O9: 2 | P9: 5 | Q9: 3.7 | R9: 4.1 | S9: 3 | T9: 0.81081081 | U9: 2.8 | V9: 2.5 | W9: 2.6 | X9: 3 | Y9: 1.2
A10: Гейдарзаде | B10: 1 | C10: 7 | D10: 6 | E10: 5 | F10: 5 | G10: 4 | H10: 8 | I10: 9 | J10: 6 | K10: 2.3 | L10: 2.2 | M10: 2.1 | N10: 3 | O10: 1.4285714 | P10: 4.5 | Q10: 3.9 | R10: 4.1 | S10: 3 | T10: 0.76923077 | U10: 2.5 | V10: 2.3 | W10: 3 | X10: 3 | Y10: 1.3043478
A11: Шубин | B11: 1 | C11: 13 | D11: 11 | E11: 10 | F11: 9 | G11: 6 | H11: 8 | I11: 10 | J11: 5 | K11: 2 | L11: 1.6 | M11: 1.4 | N11: 5 | O11: 3.5714286 | P11: 2.3 | Q11: 2 | R11: 2.5 | S11: 5 | T11: 2.5 | U11: 2 | V11: 1.3 | W11: 2 | X11: 5 | Y11: 3.8461538
A12: Астапова | B12: 0 | C12: 7 | D12: 7 | E12: 6 | F12: 5 | G12: 4 | H12: 6 | I12: 9 | J12: 6 | K12: 2.5 | L12: 3.5 | M12: 2.2 | N12: 3 | O12: 1.3636364 | P12: 3 | Q12: 3.3 | R12: 3.6 | S12: 4 | T12: 1.3333333 | U12: 1.9 | V12: 2.3 | W12: 1.5 | X12: 5 | Y12: 2.6315789
A13: Астапов | B13: 0 | C13: 4 | D13: 4 | E13: 3 | F13: 4 | G13: 3 | H13: 4 | I13: 8 | J13: 5 | K13: 3.3 | L13: 2.9 | M13: 3.5 | N13: 3 | O13: 1.0344828 | P13: 3.5 | Q13: 4 | R13: 3 | S13: 4 | T13: 1.3333333 | U13: 2 | V13: 1.8 | W13: 1.5 | X13: 5 | Y13: 3.3333333
A14: Володин | B14: 0 | C14: 8 | D14: 9 | E14: 6 | F14: 4 | G14: 3 | H14: 6 | I14: 9 | J14: 4 | K14: 3.6 | L14: 3.4 | M14: 2.8 | N14: 3 | O14: 1.0714286 | P14: 3.5 | Q14: 4 | R14: 4.1 | S14: 4 | T14: 1.1428571 | U14: 3.1 | V14: 2.3 | W14: 3.3 | X14: 4 | Y14: 1.7391304
A15: Гостев | B15: 0 | C15: 7 | D15: 4 | E15: 4 | F15: 3 | G15: 2 | H15: 8 | I15: 8 | J15: 4 | K15: 2.6 | L15: 2.1 | M15: 3.5 | N15: 4 | O15: 1.9047619 | P15: 5 | Q15: 3.9 | R15: 4.5 | S15: 3 | T15: 0.76923077 | U15: 1.6 | V15: 2 | W15: 1.9 | X15: 5 | Y15: 3.125
A16: Кандеев | B16: 0 | C16: 9 | D16: 10 | E16: 6 | F16: 6 | G16: 3 | H16: 8 | I16: 10 | J16: 4 | K16: 2.3 | L16: 2.5 | M16: 2.9 | N16: 4 | O16: 1.7391304 | P16: 4 | Q16: 3.9 | R16: 3.6 | S16: 3 | T16: 0.83333333 | U16: 2.2 | V16: 2.9 | W16: 2.1 | X16: 5 | Y16: 2.3809524
A17: Марушин | B17: 0 | C17: 6 | D17: 6 | E17: 5 | F17: 3 | G17: 1 | H17: 7 | I17: 7 | J17: 4 | K17: 3.6 | L17: 3.5 | M17: 3.4 | N17: 3 | O17: 0.88235294 | P17: 4.1 | Q17: 3.3 | R17: 3.5 | S17: 3 | T17: 0.90909091 | U17: 2.5 | V17: 3.2 | W17: 3.3 | X17: 3 | Y17: 1.2
A18: Марушин | B18: 0 | C18: 8 | D18: 9 | E18: 6 | F18: 7 | G18: 6 | H18: 12 | I18: 7 | J18: 5 | K18: 3 | L18: 1.9 | M18: 2.2 | N18: 5 | O18: 2.6315789 | P18: 2.3 | Q18: 2.4 | R18: 2.8 | S18: 5 | T18: 2.173913 | U18: 3.5 | V18: 2.5 | W18: 3 | X18: 2 | Y18: 0.8
A19: Петиков | B19: 0 | C19: 7 | D19: 6 | E19: 5 | F19: 4 | G19: 3 | H19: 11 | I19: 7 | J19: 4 | K19: 2.2 | L19: 2.5 | M19: 2.8 | N19: 4 | O19: 1.8181818 | P19: 4 | Q19: 3.9 | R19: 3.7 | S19: 3 | T19: 0.81081081 | U19: 2.1 | V19: 1.9 | W19: 2.5 | X19: 3 | Y19: 1.5789474
A20: Сафронов | B20: 0 | C20: 10 | D20: 9 | E20: 8 | F20: 6 | G20: 0 | H20: 8 | I20: 8 | J20: 4 | K20: 2.7 | L20: 3.1 | M20: 3.5 | N20: 4 | O20: 1.4814815 | P20: 3.2 | Q20: 2.8 | R20: 3.5 | S20: 4 | T20: 1.4285714 | U20: 3.3 | V20: 3.5 | W20: 3 | X20: 2 | Y20: 0.66666667
A21: Янкин | B21: 0 | C21: 12 | D21: 11 | E21: 8 | F21: 7 | G21: 4 | H21: 6 | I21: 12 | J21: 8 | K21: 2.2 | L21: 3.5 | M21: 1.4 | N21: 5 | O21: 3.5714286 | P21: 2.5 | Q21: 2.3 | R21: 2.4 | S21: 5 | T21: 2.173913 | U21: 2.5 | V21: 2 | W21: 1.9 | X21: 5 | Y21: 2.6315789

Sheet общая сводка
A1: Группа №1 (эксперимнентальная)
A2: № | B2: ФИО | C2: Возраст | D2: № задания | E2: Экономичность | H2: Вариативность | I2: Эффективность | J2: Стабильность
A3: 1 | B3: Арутюнян Э. | C3: 14 | D3: 1 | E3: 1.25 | F3: 1.45 | G3: 2.5 | I3: =эффективность!E3 -> 0.8 | J3: =стабильность!G3 -> 0.9
D4: 2 | E4: 2.1 | F4: 2.2 | G4: 2.3
D5: 3 | E5: 4 | F5: 1.9 | G5: 2.3
A6: 2 | B6: Корчагина А. | C6: 14 | D6: 1 | E6: 1.45 | F6: 1.5 | G6: 2.1 | I6: =эффективность!E4 -> 0.5 | J6: =стабильность!G4 -> 1
D7: 2 | E7: 2.2 | F7: 2.3 | G7: 2.8
D8: 3 | E8: 2.6 | F8: 2 | G8: 1.9
A9: 3 | B9: Закоптелкова М. | C9: 15 | D9: 1 | E9: 1.8 | F9: 2.9 | G9: 1.9 | I9: =эффективность!E5 -> 0.28571429 | J9: =стабильность!G5 -> 0.71428571
D10: 2 | E10: 3.4 | F10: 2.5 | G10: 3.5
D11: 3 | E11: 2.3 | F11: 3.2 | G11: 1.9
A12: 4 | B12: Голубинская А. | C12: 13 | D12: 1 | E12: 4.3 | G12: 3.2 | I12: =эффективность!E6 -> 0.11111111 | J12: =стабильность!G6 -> 0.75
D13: 2 | F13: 4
D14: 3 | F14: 5.5 | G14: 3
A15: 5 | B15: Алиев А. | C15: 14 | D15: 1 | E15: 1.7 | F15: 2.3 | G15: 2.1 | I15: =эффективность!E7 -> 0.5 | J15: =стабильность!G7 -> 0.66666667
D16: 2 | E16: 4.1 | F16: 4 | G16: 3.1
D17: 3 | E17: 2.3 | F17: 2.5 | G17: 3.2
A18: 6 | B18: Устинов Т. | C18: 15 | D18: 1 | F18: 2.25 | G18: 3 | I18: =эффективность!E8 -> 0.16666667 | J18: =стабильность!G8 -> 0.5
D19: 2 | E19: 4 | F19: 2.3 | G19: 3.7
D20: 3 | E20: 4.3 | F20: 3 | G20: 2.5
A21: 7 | B21: Закоптелков С. | C21: 13 | D21: 1 | E21: 1.9 | F21: 2 | G21: 2 | I21: =эффективность!E9 -> 0.45454545 | J21: =стабильность!G9 -> 0.5
D22: 2 | F22: 4.5 | G22: 3.9
D23: 3 | E23: 2.3 | F23: 2.5 | G23: 2.3
A24: 8 | B24: Ефремов Е. | C24: 13 | D24: 1 | E24: 2.6 | F24: 2.8 | G24: 2.5 | I24: =эффективность!E10 -> 0.2 | J24: =стабильность!G10 -> 0.57142857
D25: 2 | E25: 5 | F25: 3.7 | G25: 4.1
D26: 3 | E26: 2 | F26: 2.2 | G26: 2.3
A27: 9 | B27: Гейдарзаде У. | C27: 14 | D27: 1 | E27: 2.5 | F27: 2.3 | G27: 3 | I27: =эффективность!E11 -> 0.5 | J27: =стабильность!G11 -> 0.71428571
D28: 2 | E28: 4.5 | F28: 3.9 | G28: 4.1
D29: 3 | E29: 2.3 | F29: 2.2 | G29: 2.1
A30: 10 | B30: Шубин И. | C30: 13 | D30: 1 | E30: 2 | F30: 2 | G30: 1.3 | I30: =эффективность!E12 -> 0.75 | J30: =стабильность!G12 -> 0.69230769
D31: 2 | E31: 2.3 | F31: 2 | G31: 2.5
D32: 3 | E32: 2 | F32: 1.6 | G32: 1.4
A37: Группа №2 (контрольная)
A38: № | B38: ФИО | C38: Возраст | D38: № задания | E38: Экономичность | H38: Вариативность | I38: Эффективность | J38: Стабильность
A39: 1 | B39: Астапова К. | C39: 13 | D39: 1 | E39: 1.9 | F39: 2.3 | G39: 1.5
D40: 2 | E40: 3 | F40: 3.3 | G40: 3.6
D41: 3 | E41: 2.5 | F41: 3.5 | G41: 2.2
A42: 2 | B42: Астапов М. | C42: 15 | D42: 1 | E42: 2 | F42: 1.8 | G42: 1.5
D43: 2 | E43: 3.5 | F43: 4 | G43: 3
D44: 3 | E44: 3.3 | F44: 2.9 | G44: 3.5
...

Sheet экономичность (иппон-сейо-нагэ)
A1: Группа №1 (эксперимнентальная)
A2: № п/п | B2: ФИО | C2: Специализация | D2: Результат 1 попытки | E2: Результат 2 попытки | F2: Результат 3 попытки | G2: среднее время выполнения приема | H2: минимальное время выполнения приема (лучшая попытка) | I2: Баллы (от 1 до 5) | J2: экономичность = качество выполнения/ затраченное время | K2: среднее минимальное время выполнения приема в группе | L2: средний балл за качество выполнения в группе | M2: средняя экономичность в группе
A3: 1 | B3: Арутюнян Э. | C3: дзюдо | D3: 1.25 | E3: 1.45 | F3: 2.5 | G3: =AVERAGE(D3:F3) -> 1.7333333 | H3: =MIN(D3:F3) -> 1.25 | I3: 5 | J3: =I3/H3 -> 4 | K3: =AVERAGE(H3:H12) -> 1.965 | L3: =AVERAGE(I3:I12) -> 3.6 | M3: =AVERAGE(J3:J12) -> 2.1355666
A4: 2 | B4: Корчагина А. | C4: дзюдо | D4: 1.45 | E4: 1.5 | F4: 2.1 | G4: =AVERAGE(D4:F4) -> 1.6833333 | H4: =MIN(D4:F4) -> 1.45 | I4: 5 | J4: =I4/H4 -> 3.4482759
A5: 3 | B5: Закоптелкова М. | C5: дзюдо | D5: 1.8 | E5: 1.9 | F5: 2.9 | G5: =AVERAGE(D5:F5) -> 2.2 | H5: =MIN(D5:F5) -> 1.8 | I5: 3 | J5: =I5/H5 -> 1.6666667
A6: 4 | B6: Голубинская А. | C6: дзюдо | D6: 4.3 | E6: 3.2 | G6: =AVERAGE(D6:F6) -> 3.75 | H6: =MIN(D6:F6) -> 3.2 | I6: 2 | J6: =I6/H6 -> 0.625
A7: 5 | B7: Алиев А. | C7: дзюдо | D7: 1.7 | E7: 2.3 | F7: 2.1 | G7: =AVERAGE(D7:F7) -> 2.0333333 | H7: =MIN(D7:F7) -> 1.7 | I7: 4 | J7: =I7/H7 -> 2.3529412
A8: 6 | B8: Устинов Т. | C8: дзюдо | D8: 2.25 | E8: 3 | G8: =AVERAGE(D8:F8) -> 2.625 | H8: =MIN(D8:F8) -> 2.25 | I8: 3 | J8: =I8/H8 -> 1.3333333
A9: 7 | B9: Закоптелков С. | C9: дзюдо | D9: 1.9 | E9: 2 | F9: 2 | G9: =AVERAGE(D9:F9) -> 1.9666667 | H9: =MIN(D9:F9) -> 1.9 | I9: 3 | J9: =I9/H9 -> 1.5789474
A10: 8 | B10: Ефремов Е. | C10: дзюдо | D10: 2.8 | E10: 2.5 | F10: 2.6 | G10: =AVERAGE(D10:F10) -> 2.6333333 | H10: =MIN(D10:F10) -> 2.5 | I10: 3 | J10: =I10/H10 -> 1.2
A11: 9 | B11: Гейдарзаде У. | C11: дзюдо | D11: 2.5 | E11: 2.3 | F11: 3 | G11: =AVERAGE(D11:F11) -> 2.6 | H11: =MIN(D11:F11) -> 2.3 | I11: 3 | J11: =I11/H11 -> 1.3043478
A12: 10 | B12: Шубин И. | C12: дзюдо | D12: 2 | E12: 1.3 | F12: 2 | G12: =AVERAGE(D12:F12) -> 1.7666667 | H12: =MIN(D12:F12) -> 1.3 | I12: 5 | J12: =I12/H12 -> 3.8461538
A18: Группа №2 (контрольная)
A19: № п/п | B19: ФИО | C19: Специализация | D19: Результат 1 попытки | E19: Результат 2 попытки | F19: Результат 3 попытки | G19: среднее время выполнения приема | H19: минимальное время выполнения приема (лучшая попытка) | I19: Баллы (от 1 до 5) | J19: экономичность = качество выполнения/ затраченное время | K19: среднее минимальное время выполнения приема в группе | L19: средний балл за качество выполнения в группе | M19: средняя экономичность в группе
A20: 1 | B20: Астапова К. | C20: дзюдо | D20: 1.9 | E20: 2.3 | F20: 1.5 | G20: =AVERAGE(D20:F20) -> 1.9 | H20: =MIN(D20:F20) -> 1.5 | I20: 5 | J20: =I20/G20 -> 2.6315789 | K20: =AVERAGE(H20:H29) -> 2.08 | L20: =AVERAGE(I20:I29) -> 3.9 | M20: =AVERAGE(J20:J29) -> 2.0087188
A21: 2 | B21: Астапов М. | C21: дзюдо | D21: 2 | E21: 1.8 | F21: 1.5 | G21: =AVERAGE(D21:F21) -> 1.7666667 | H21: =MIN(D21:F21) -> 1.5 | I21: 5 | J21: =I21/H21 -> 3.3333333
A22: 3 | B22: Володин М. | C22: дзюдо | D22: 3.1 | E22: 2.3 | F22: 3.3 | G22: =AVERAGE(D22:F22) -> 2.9 | H22: =MIN(D22:F22) -> 2.3 | I22: 4 | J22: =I22/H22 -> 1.7391304
A23: 4 | B23: Гостев К. | C23: дзюдо | D23: 1.6 | E23: 2 | F23: 1.9 | G23: =AVERAGE(D23:F23) -> 1.8333333 | H23: =MIN(D23:F23) -> 1.6 | I23: 5 | J23: =I23/H23 -> 3.125
A24: 5 | B24: Кандеев А. | C24: дзюдо | D24: 2.2 | E24: 2.9 | F24: 2.1 | G24: =AVERAGE(D24:F24) -> 2.4 | H24: =MIN(D24:F24) -> 2.1 | I24: 5 | J24: =I24/H24 -> 2.3809524
A25: 6 | B25: Марушин Д. | C25: дзюдо | D25: 2.5 | E25: 3.2 | F25: 3.3 | G25: =AVERAGE(D25:F25) -> 3 | H25: =MIN(D25:F25) -> 2.5 | I25: 3 | J25: =I25/H25 -> 1.2
A26: 7 | B26: Марушин Т. | C26: дзюдо | D26: 3.5 | E26: 2.5 | F26: 3 | G26: =AVERAGE(D26:F26) -> 3 | H26: =MIN(D26:F26) -> 2.5 | I26: 2 | J26: =I26/H26 -> 0.8
A27: 8 | B27: Петиков В. | C27: дзюдо | D27: 2.1 | E27: 1.9 | F27: 2.5 | G27: =AVERAGE(D27:F27) -> 2.1666667 | H27: =MIN(D27:F27) -> 1.9 | I27: 3 | J27: =I27/H27 -> 1.5789474
A28: 9 | B28: Сафронов А. | C28: дзюдо | D28: 3.3 | E28: 3.5 | F28: 3 | G28: =AVERAGE(D28:F28) -> 3.2666667 | H28: =MIN(D28:F28) -> 3 | I28: 2 | J28: =I28/H28 -> 0.66666667
A29: 10 | B29: Янкин М. | C29: дзюдо | D29: 2.5 | E29: 2 | F29: 1.9 | G29: =AVERAGE(D29:F29) -> 2.1333333 | H29: =MIN(D29:F29) -> 1.9 | I29: 5 | J29: =I29/H29 -> 2.6315789

Sheet экономичность (суми-гаэши)
A1: Группа №1 (эксперимнентальная)
A2: № п/п | B2: ФИО | C2: Специализация | D2: Результат 1 попытки | E2: Результат 2 попытки | F2: Результат 3 попытки | G2: среднее время выполнения приема | H2: минимальное время выполнения приема (лучшая попытка) | I2: Баллы (от 1 до 5) | J2: экономичность = качество выполнения/ затраченное время | K2: среднее минимальное время выполнения приема в группе | L2: средний балл за качество выполнения в группе | M2: средняя экономичность в группе
A3: 1 | B3: Арутюнян Э. | C3: дзюдо | D3: 2.1 | E3: 2.2 | F3: 2.3 | G3: =AVERAGE(D3:F3) -> 2.2 | H3: =MIN(D3:F3) -> 2.1 | I3: 5 | J3: =I3/H3 -> 2.3809524 | K3: =AVERAGE(H3:H12) -> 2.97 | L3: =AVERAGE(I3:I12) -> 3.8 | M3: =AVERAGE(J3:J12) -> 1.4632405
A4: 2 | B4: Корчагина А. | C4: дзюдо | D4: 2.2 | E4: 2.3 | F4: 2.8 | G4: =AVERAGE(D4:F4) -> 2.4333333 | H4: =MIN(D4:F4) -> 2.2 | I4: 5 | J4: =I4/H4 -> 2.2727273
A5: 3 | B5: Закоптелкова М. | C5: дзюдо | D5: 3.4 | E5: 2.5 | F5: 3.5 | G5: =AVERAGE(D5:F5) -> 3.1333333 | H5: =MIN(D5:F5) -> 2.5 | I5: 4 | J5: =I5/H5 -> 1.6
A6: 4 | B6: Голубинская А. | C6: дзюдо | E6: 4 | G6: =AVERAGE(D6:F6) -> 4 | H6: =MIN(D6:F6) -> 4 | I6: 2 | J6: =I6/H6 -> 0.5
A7: 5 | B7: Алиев А. | C7: дзюдо | D7: 4.1 | E7: 4 | F7: 3.1 | G7: =AVERAGE(D7:F7) -> 3.7333333 | H7: =MIN(D7:F7) -> 3.1 | I7: 4 | J7: =I7/H7 -> 1.2903226
A8: 6 | B8: Устинов Т. | C8: дзюдо | D8: 4 | E8: 2.3 | F8: 3.7 | G8: =AVERAGE(D8:F8) -> 3.3333333 | H8: =MIN(D8:F8) -> 2.3 | I8: 4 | J8: =I8/H8 -> 1.7391304
A9: 7 | B9: Закоптелков С. | C9: дзюдо | E9: 4.5 | F9: 3.9 | G9: =AVERAGE(D9:F9) -> 4.2 | H9: =MIN(D9:F9) -> 3.9 | I9: 3 | J9: =I9/H9 -> 0.76923077
A10: 8 | B10: Ефремов Е. | C10: дзюдо | D10: 5 | E10: 3.7 | F10: 4.1 | G10: =AVERAGE(D10:F10) -> 4.2666667 | H10: =MIN(D10:F10) -> 3.7 | I10: 3 | J10: =I10/H10 -> 0.81081081
A11: 9 | B11: Гейдарзаде У. | C11: дзюдо | D11: 4.5 | E11: 3.9 | F11: 4.1 | G11: =AVERAGE(D11:F11) -> 4.1666667 | H11: =MIN(D11:F11) -> 3.9 | I11: 3 | J11: =I11/H11 -> 0.76923077
A12: 10 | B12: Шубин И. | C12: дзюдо | D12: 2.3 | E12: 2 | F12: 2.5 | G12: =AVERAGE(D12:F12) -> 2.2666667 | H12: =MIN(D12:F12) -> 2 | I12: 5 | J12: =I12/H12 -> 2.5
A21: Группа №2 (контрольная)
A22: № п/п | B22: ФИО | C22: Специализация | D22: Результат 1 попытки | E22: Результат 2 попытки | F22: Результат 3 попытки | G22: среднее время выполнения приема | H22: минимальное время выполнения приема (лучшая попытка) | I22: Баллы (от 1 до 5) | J22: экономичность = качество выполнения/ затраченное время | K22: среднее минимальное время выполнения приема в группе | L22: средний балл за качество выполнения в группе | M22: средняя экономичность в группе
A23: 1 | B23: Астапова К. | C23: дзюдо | D23: 3 | E23: 3.3 | F23: 3.6 | G23: =AVERAGE(D23:F23) -> 3.3 | H23: =MIN(D23:F23) -> 3 | I23: 4 | J23: =I23/H23 -> 1.3333333 | K23: =AVERAGE(H23:H32) -> 3.14 | L23: =AVERAGE(I23:I32) -> 3.8 | M23: =AVERAGE(J23:J32) -> 1.2908387
A24: 2 | B24: Астапов М. | C24: дзюдо | D24: 3.5 | E24: 4 | F24: 3 | G24: =AVERAGE(D24:F24) -> 3.5 | H24: =MIN(D24:F24) -> 3 | I24: 4 | J24: =I24/H24 -> 1.3333333
A25: 3 | B25: Володин М. | C25: дзюдо | D25: 3.5 | E25: 4 | F25: 4.1 | G25: =AVERAGE(D25:F25) -> 3.8666667 | H25: =MIN(D25:F25) -> 3.5 | I25: 4 | J25: =I25/H25 -> 1.1428571
A26: 4 | B26: Гостев К. | C26: дзюдо | D26: 5 | E26: 3.9 | F26: 4.5 | G26: =AVERAGE(D26:F26) -> 4.4666667 | H26: =MIN(D26:F26) -> 3.9 | I26: 3 | J26: =I26/H26 -> 0.76923077
A27: 5 | B27: Кандеев А. | C27: дзюдо | D27: 4 | E27: 3.9 | F27: 3.6 | G27: =AVERAGE(D27:F27) -> 3.8333333 | H27: =MIN(D27:F27) -> 3.6 | I27: 3 | J27: =I27/H27 -> 0.83333333
A28: 6 | B28: Марушин Д. | C28: дзюдо | D28: 4.1 | E28: 3.3 | F28: 3.5 | G28: =AVERAGE(D28:F28) -> 3.6333333 | H28: =MIN(D28:F28) -> 3.3 | I28: 3 | J28: =I28/H28 -> 0.90909091
A29: 7 | B29: Марушин Т. | C29: дзюдо | D29: 2.3 | E29: 2.4 | F29: 2.8 | G29: =AVERAGE(D29:F29) -> 2.5 | H29: =MIN(D29:F29) -> 2.3 | I29: 5 | J29: =I29/H29 -> 2.173913
A30: 8 | B30: Петиков В. | C30: дзюдо | D30: 4 | E30: 3.9 | F30: 3.7 | G30: =AVERAGE(D30:F30) -> 3.8666667 | H30: =MIN(D30:F30) -> 3.7 | I30: 3 | J30: =I30/H30 -> 0.81081081
A31: 9 | B31: Сафронов А. | C31: дзюдо | D31: 3.2 | E31: 2.8 | F31: 3.5 | G31: =AVERAGE(D31:F31) -> 3.1666667 | H31: =MIN(D31:F31) -> 2.8 | I31: 4 | J31: =I31/H31 -> 1.4285714
A32: 10 | B32: Янкин М. | C32: дзюдо | D32: 2.5 | E32: 2.3 | F32: 2.4 | G32: =AVERAGE(D32:F32) -> 2.4 | H32: =MIN(D32:F32) -> 2.3 | I32: 5 | J32: =I32/H32 -> 2.173913

Sheet экономичность (кеса-гатамэ)
A1: Группа №1 (эксперимнентальная)
A2: № п/п | B2: ФИО | C2: Специализация | D2: Результат 1 попытки | E2: Результат 2 попытки | F2: Результат 3 попытки | G2: среднее время выполнения приема | H2: минимальное время выполнения приема (лучшая попытка) | I2: Баллы (от 1 до 5) | J2: экономичность = качество выполнения/ затраченное время | K2: среднее минимальное время выполнения приема в группе | L2: средний балл за качество выполнения в группе | M2: средняя экономичность в группе
A3: 1 | B3: Арутюнян Э. | C3: дзюдо | D3: 4 | E3: 1.9 | F3: 2.3 | G3: =AVERAGE(D3:F3) -> 2.7333333 | H3: =MIN(D3:F3) -> 1.9 | I3: 5 | J3: =I3/H3 -> 2.6315789 | K3: =AVERAGE(H3:H12) -> 2.13 | L3: =AVERAGE(I3:I12) -> 3.8 | M3: =AVERAGE(J3:J12) -> 1.9404882
A4: 2 | B4: Корчагина А. | C4: дзюдо | D4: 2.6 | E4: 2 | F4: 1.9 | G4: =AVERAGE(D4:F4) -> 2.1666667 | H4: =MIN(D4:F4) -> 1.9 | I4: 5 | J4: =I4/H4 -> 2.6315789
A5: 3 | B5: Закоптелкова М. | C5: дзюдо | D5: 2.3 | E5: 3.2 | F5: 1.9 | G5: =AVERAGE(D5:F5) -> 2.4666667 | H5: =MIN(D5:F5) -> 1.9 | I5: 5 | J5: =I5/H5 -> 2.6315789
A6: 4 | B6: Голубинская А. | C6: дзюдо | E6: 5.5 | F6: 3 | G6: =AVERAGE(D6:F6) -> 4.25 | H6: =MIN(D6:F6) -> 3 | I6: 2 | J6: =I6/H6 -> 0.66666667
A7: 5 | B7: Алиев А. | C7: дзюдо | D7: 2.3 | E7: 2.5 | F7: 3.2 | G7: =AVERAGE(D7:F7) -> 2.6666667 | H7: =MIN(D7:F7) -> 2.3 | I7: 4 | J7: =I7/H7 -> 1.7391304
A8: 6 | B8: Устинов Т. | C8: дзюдо | D8: 4.3 | E8: 3 | F8: 2.5 | G8: =AVERAGE(D8:F8) -> 3.2666667 | H8: =MIN(D8:F8) -> 2.5 | I8: 2 | J8: =I8/H8 -> 0.8
A9: 7 | B9: Закоптелков С. | C9: дзюдо | D9: 2.3 | E9: 2.5 | F9: 2.3 | G9: =AVERAGE(D9:F9) -> 2.3666667 | H9: =MIN(D9:F9) -> 2.3 | I9: 3 | J9: =I9/H9 -> 1.3043478
A10: 8 | B10: Ефремов Е. | C10: дзюдо | D10: 2 | E10: 2.2 | F10: 2.3 | G10: =AVERAGE(D10:F10) -> 2.1666667 | H10: =MIN(D10:F10) -> 2 | I10: 4 | J10: =I10/H10 -> 2
A11: 9 | B11: Гейдарзаде У. | C11: дзюдо | D11: 2.3 | E11: 2.2 | F11: 2.1 | G11: =AVERAGE(D11:F11) -> 2.2 | H11: =MIN(D11:F11) -> 2.1 | I11: 3 | J11: =I11/H11 -> 1.4285714
A12: 10 | B12: Шубин И. | C12: дзюдо | D12: 2 | E12: 1.6 | F12: 1.4 | G12: =AVERAGE(D12:F12) -> 1.6666667 | H12: =MIN(D12:F12) -> 1.4 | I12: 5 | J12: =I12/H12 -> 3.5714286
A19: Группа №2 (контрольная)
A20: № п/п | B20: ФИО | C20: Специализация | D20: Результат 1 попытки | E20: Результат 2 попытки | F20: Результат 3 попытки | G20: среднее время выполнения приема | H20: минимальное время выполнения приема (лучшая попытка) | I20: Баллы (от 1 до 5) | J20: экономичность = качество выполнения/ затраченное время | K20: среднее минимальное время выполнения приема в группе | L20: средний балл за качество выполнения в группе | M20: средняя экономичность в группе
A21: 1 | B21: Астапова К. | C21: дзюдо | D21: 2.5 | E21: 3.5 | F21: 2.2 | G21: =AVERAGE(D21:F21) -> 2.7333333 | H21: =MIN(D21:F21) -> 2.2 | I21: 3 | J21: =I21/H21 -> 1.3636364 | K21: =AVERAGE(H21:H30) -> 2.39 | L21: =AVERAGE(I21:I30) -> 3.8 | M21: =AVERAGE(J21:J30) -> 1.7498464
A22: 2 | B22: Астапов М. | C22: дзюдо | D22: 3.3 | E22: 2.9 | F22: 3.5 | G22: =AVERAGE(D22:F22) -> 3.2333333 | H22: =MIN(D22:F22) -> 2.9 | I22: 3 | J22: =I22/H22 -> 1.0344828
A23: 3 | B23: Володин М. | C23: дзюдо | D23: 3.6 | E23: 3.4 | F23: 2.8 | G23: =AVERAGE(D23:F23) -> 3.2666667 | H23: =MIN(D23:F23) -> 2.8 | I23: 3 | J23: =I23/H23 -> 1.0714286
A24: 4 | B24: Гостев К. | C24: дзюдо | D24: 2.6 | E24: 2.1 | F24: 3.5 | G24: =AVERAGE(D24:F24) -> 2.7333333 | H24: =MIN(D24:F24) -> 2.1 | I24: 4 | J24: =I24/H24 -> 1.9047619
A25: 5 | B25: Кандеев А. | C25: дзюдо | D25: 2.3 | E25: 2.5 | F25: 2.9 | G25: =AVERAGE(D25:F25) -> 2.5666667 | H25: =MIN(D25:F25) -> 2.3 | I25: 4 | J25: =I25/H25 -> 1.7391304
A26: 6 | B26: Марушин Д. | C26: дзюдо | D26: 3.6 | E26: 3.5 | F26: 3.4 | G26: =AVERAGE(D26:F26) -> 3.5 | H26: =MIN(D26:F26) -> 3.4 | I26: 3 | J26: =I26/H26 -> 0.88235294
A27: 7 | B27: Марушин Т. | C27: дзюдо | D27: 3 | E27: 1.9 | F27: 2.2 | G27: =AVERAGE(D27:F27) -> 2.3666667 | H27: =MIN(D27:F27) -> 1.9 | I27: 5 | J27: =I27/H27 -> 2.6315789
A28: 8 | B28: Петиков В. | C28: дзюдо | D28: 2.2 | E28: 2.5 | F28: 2.8 | G28: =AVERAGE(D28:F28) -> 2.5 | H28: =MIN(D28:F28) -> 2.2 | I28: 4 | J28: =I28/H28 -> 1.8181818
A29: 9 | B29: Сафронов А. | C29: дзюдо | D29: 2.7 | E29: 3.1 | F29: 3.5 | G29: =AVERAGE(D29:F29) -> 3.1 | H29: =MIN(D29:F29) -> 2.7 | I29: 4 | J29: =I29/H29 -> 1.4814815
A30: 10 | B30: Янкин М. | C30: дзюдо | D30: 2.2 | E30: 3.5 | F30: 1.4 | G30: =AVERAGE(D30:F30) -> 2.3666667 | H30: =MIN(D30:F30) -> 1.4 | I30: 5 | J30: =I30/H30 -> 3.5714286

Sheet вариативность (броски)
A1: Группа №1 (эксперимнентальная)
A2: Названия приемов | B2: Арутюнян Э. | C2: Корчагина А. | D2: Закоптелкова М. | E2: Голубинская А. | F2: Алиев А. | G2: Устинов | H2: Закоптелков С. | I2: Ефремов Е. | J2: Гейдарзаде У. | K2: Шубин И. | L2: всего продемонстрировали отдельную технику: | M2: Доля каждого приема Pi | N2: Pi*ln(Pi) | O2: H' (Индекс Шеннона) | P2: J' (равномерность)
A3: иппон-сейо-нагэ | B3: 1 | C3: 1 | E3: 1 | F3: 1 | H3: 1 | I3: 1 | J3: 1 | K3: 1 | L3: =SUM(B3:K3) -> 8 | M3: =L3/$L$21 -> 0.1025641 | N3: =M3*LN(M3) -> -0.23356588 | O3: =-SUM(N3:N20) -> 2.6230107 | P3: =O3/$N$21 -> 0.90749943
A4: марате-сейо-нагэ | B4: 1 | C4: 1 | D4: 1 | F4: 1 | G4: 1 | H4: 1 | I4: 1 | J4: 1 | K4: 1 | L4: =SUM(B4:K4) -> 9 | M4: =L4/$L$21 -> 0.11538462 | N4: =M4*LN(M4) -> -0.24917126 | O4: Этот индекс нужен????
A5: марате-сейо-нагэ с односторонним захватом | J5: 1 | L5: =SUM(B5:K5) -> 1 | M5: =L5/$L$21 -> 0.012820513 | N5: =M5*LN(M5) -> -0.055855241 | Q5: где, S=18 (число видов приёмов), pi​ — доля общего числа выполненных раз этого приёма от общего количества всех выполненных приёмов.
A6: о-госи | B6: 1 | C6: 1 | D6: 1 | F6: 1 | G6: 1 | I6: 1 | J6: 1 | K6: 1 | L6: =SUM(B6:K6) -> 8 | M6: =L6/$L$21 -> 0.1025641 | N6: =M6*LN(M6) -> -0.23356588
A7: о-сото-отоси | C7: 1 | D7: 1 | E7: 1 | G7: 1 | H7: 1 | I7: 1 | J7: 1 | L7: =SUM(B7:K7) -> 7 | M7: =L7/$L$21 -> 0.08974359 | N7: =M7*LN(M7) -> -0.21635373
A8: тай-отоси | B8: 1 | C8: 1 | D8: 1 | E8: 1 | F8: 1 | G8: 1 | K8: 1 | L8: =SUM(B8:K8) -> 7 | M8: =L8/$L$21 -> 0.08974359 | N8: =M8*LN(M8) -> -0.21635373
A9: учи-мата | B9: 1 | C9: 1 | D9: 1 | E9: 1 | F9: 1 | G9: 1 | H9: 1 | K9: 1 | L9: =SUM(B9:K9) -> 8 | M9: =L9/$L$21 -> 0.1025641 | N9: =M9*LN(M9) -> -0.23356588
A10: тсури-госи | B10: 1 | L10: =SUM(B10:K10) -> 1 | M10: =L10/$L$21 -> 0.012820513 | N10: =M10*LN(M10) -> -0.055855241
A11: соде-тсурикоми-госи | B11: 1 | C11: 1 | D11: 1 | J11: 1 | L11: =SUM(B11:K11) -> 4 | M11: =L11/$L$21 -> 0.051282051 | N11: =M11*LN(M11) -> -0.15232895
A12: о-учи-гари | B12: 1 | E12: 1 | F12: 1 | I12: 1 | K12: 1 | L12: =SUM(B12:K12) -> 5 | M12: =L12/$L$21 -> 0.064102564 | N12: =M12*LN(M12) -> -0.17610711
A13: ко-учи-гари | C13: 1 | D13: 1 | E13: 1 | F13: 1 | H13: 1 | J13: 1 | K13: 1 | L13: =SUM(B13:K13) -> 7 | M13: =L13/$L$21 -> 0.08974359 | N13: =M13*LN(M13) -> -0.21635373
A14: дэ-аси-харай (боковая подсечка) | C14: 1 | H14: 1 | I14: 1 | K14: 1 | L14: =SUM(B14:K14) -> 4 | M14: =L14/$L$21 -> 0.051282051 | N14: =M14*LN(M14) -> -0.15232895
A15: ко-учи-гакэ (классический захват) | G15: 1 | L15: =SUM(B15:K15) -> 1 | M15: =L15/$L$21 -> 0.012820513 | N15: =M15*LN(M15) -> -0.055855241
A16: ко-учи-макикоми (захват под плечо) | K16: 1 | L16: =SUM(B16:K16) -> 1 | M16: =L16/$L$21 -> 0.012820513 | N16: =M16*LN(M16) -> -0.055855241
A17: ко-сото-гакэ (зацеп снаружи) | G17: 1 | L17: =SUM(B17:K17) -> 1 | M17: =L17/$L$21 -> 0.012820513 | N17: =M17*LN(M17) -> -0.055855241
A18: хидза-гурума | F18: 1 | G18: 1 | J18: 1 | K18: 1 | L18: =SUM(B18:K18) -> 4 | M18: =L18/$L$21 -> 0.051282051 | N18: =M18*LN(M18) -> -0.15232895
A19: хараи-госи | F19: 1 | L19: =SUM(B19:K19) -> 1 | M19: =L19/$L$21 -> 0.012820513 | N19: =M19*LN(M19) -> -0.055855241
A20: ко-сото-гари (подсечка под пятку снаружи) | J20: 1 | L20: =SUM(B20:K20) -> 1 | M20: =L20/$L$21 -> 0.012820513 | N20: =M20*LN(M20) -> -0.055855241
A21: Всего различных приемов у спортсмена: | B21: =SUM(B3:B20) -> 8 | C21: =SUM(C3:C20) -> 9 | D21: =SUM(D3:D20) -> 7 | E21: =SUM(E3:E20) -> 6 | F21: =SUM(F3:F20) -> 9 | G21: =SUM(G3:G20) -> 8 | H21: =SUM(H3:H20) -> 6 | I21: =SUM(I3:I20) -> 6 | ... L21: =SUM(L3:L20) -> 78 | M21: H'max= | N21: =LN(B23) -> 2.8903718
A23: всего уникальных технических приемов в группе: | B23: =COUNTA(A3:A20) -> 18
A25: Индекс вариативности на спортсмена | E25: =SUM(B21:K21)/10 -> 7.8
A26: вариативность техники в тати-вадза в группе 1 | B26: =B23/E25 -> 2.3076923
A38: Группа №2 (контрольная)
A39: Названия приемов | B39: Астапова К. | C39: Астапов М. | D39: Володин М. | E39: Гостев К. | F39: Кандеев А. | G39: Марушин Д. | H39: Марушин Т. | I39: Петиков В. | J39: Сафронов А. | K39: Янкин М. | L39: всего продемонстрировали отдельную технику:
A40: иппон-сейо-нагэ | B40: 1 | C40: 1 | E40: 1 | F40: 1 | H40: 1 | I40: 1 | J40: 1 | K40: 1 | L40: =SUM(B40:K40) -> 8
A41: марате-сейо-нагэ | B41: 1 | C41: 1 | D41: 1 | F41: 1 | G41: 1 | H41: 1 | I41: 1 | J41: 1 | K41: 1 | L41: =SUM(B41:K41) -> 9
A42: марате-сейо-нагэ с односторонним захватом | B42: 1 | J42: 1 | K42: 1 | L42: =SUM(B42:K42) -> 3
A43: о-госи | B43: 1 | C43: 1 | D43: 1 | F43: 1 | G43: 1 | I43: 1 | J43: 1 | K43: 1 | L43: =SUM(B43:K43) -> 8
A44: о-сото-отоси | C44: 1 | D44: 1 | E44: 1 | H44: 1 | I44: 1 | J44: 1 | L44: =SUM(B44:K44) -> 6
A45: тай-отоси | B45: 1 | D45: 1 | E45: 1 | F45: 1 | G45: 1 | K45: 1 | L45: =SUM(B45:K45) -> 6
A46: учи-мата | B46: 1 | C46: 1 | D46: 1 | E46: 1 | F46: 1 | G46: 1 | H46: 1 | K46: 1 | L46: =SUM(B46:K46) -> 8
A47: тсури-госи | L47: =SUM(B47:K47) -> 0
A48: соде-тсурикоми-госи | C48: 1 | D48: 1 | G48: 1 | J48: 1 | L48: =SUM(B48:K48) -> 4
A49: о-учи-гари | B49: 1 | E49: 1 | I49: 1 | K49: 1 | L49: =SUM(B49:K49) -> 4
A50: ко-учи-гари | C50: 1 | D50: 1 | E50: 1 | F50: 1 | H50: 1 | J50: 1 | K50: 1 | L50: =SUM(B50:K50) -> 7
A51: дэ-аси-харай (боковая подсечка) | H51: 1 | I51: 1 | K51: 1 | L51: =SUM(B51:K51) -> 3
A52: ко-учи-гакэ (классический захват) | B52: 1 | E52: 1 | F52: 1 | G52: 1 | K52: 1 | L52: =SUM(B52:K52) -> 5
A53: ко-учи-макикоми (захват под плечо) | C53: 1 | K53: 1 | L53: =SUM(B53:K53) -> 2
...

Sheet вариативность (удержания)
A1: Группа №1 (эксперимнентальная)
A2: Названия приемов | B2: Арутюнян Э. | C2: Корчагина А. | D2: Закоптелкова М. | E2: Голубинская А. | F2: Алиев А. | G2: Устинов | H2: Закоптелков С. | I2: Ефремов Е. | J2: Гейдарзаде У. | K2: Шубин И. | L2: всего продемонстрировали отдельную технику: | M2: Доля каждого приема Pi | N2: Pi*ln(Pi) | O2: H' (Индекс Шеннона) | P2: J' (равномерность)
A3: кеса-гатамэ | B3: 1 | C3: 1 | D3: 1 | E3: 1 | F3: 1 | G3: 1 | H3: 1 | I3: 1 | J3: 1 | K3: 1 | L3: =SUM(B3:K3) -> 10 | M3: =L3/$L$12 -> 0.19607843 | N3: =M3*LN(M3) -> -0.31945893 | O3: =-SUM(N3:N11) -> 2.0619074 | P3: =O3/$N$12 -> 0.9384145
A4: ёко-сихо-гатамэ (захват с ногой и рукой) | B4: 1 | C4: 1 | D4: 1 | F4: 1 | J4: 1 | L4: =SUM(B4:K4) -> 5 | M4: =L4/$L$12 -> 0.098039216 | N4: =M4*LN(M4) -> -0.22768507
A5: ёко-сихо-гатамэ (захват с рукой) | B5: 1 | C5: 1 | D5: 1 | E5: 1 | F5: 1 | H5: 1 | I5: 1 | J5: 1 | L5: =SUM(B5:K5) -> 8 | M5: =L5/$L$12 -> 0.15686275 | N5: =M5*LN(M5) -> -0.29057005
A6: татэ-сихо-гатамэ | B6: 1 | C6: 1 | F6: 1 | G6: 1 | H6: 1 | I6: 1 | J6: 1 | K6: 1 | L6: =SUM(B6:K6) -> 8 | M6: =L6/$L$12 -> 0.15686275 | N6: =M6*LN(M6) -> -0.29057005
A7: кузурэ-кеса-гатамэ | B7: 1 | E7: 1 | H7: 1 | L7: =SUM(B7:K7) -> 3 | M7: =L7/$L$12 -> 0.058823529 | N7: =M7*LN(M7) -> -0.16665961
A8: ёко-сихо-гатамэ (захват с рукой и головой) | G8: 1 | H8: 1 | J8: 1 | K8: 1 | L8: =SUM(B8:K8) -> 4 | M8: =L8/$L$12 -> 0.078431373 | N8: =M8*LN(M8) -> -0.19964951
A9: ками-сихо-гатамэ | B9: 1 | C9: 1 | D9: 1 | K9: 1 | L9: =SUM(B9:K9) -> 4 | M9: =L9/$L$12 -> 0.078431373 | N9: =M9*LN(M9) -> -0.19964951
A10: ёко-сихо-гатамэ (захват с ногой и головой) | B10: 1 | E10: 1 | F10: 1 | G10: 1 | H10: 1 | I10: 1 | J10: 1 | K10: 1 | L10: =SUM(B10:K10) -> 8 | M10: =L10/$L$12 -> 0.15686275 | N10: =M10*LN(M10) -> -0.29057005
A11: кузурэ-ками-сихо-гатамэ | G11: 1 | L11: =SUM(B11:K11) -> 1 | M11: =L11/$L$12 -> 0.019607843 | N11: =M11*LN(M11) -> -0.07709462
A12: Всего различных приемов у спортсмена: | B12: =SUM(B3:B11) -> 7 | C12: =SUM(C3:C11) -> 5 | D12: =SUM(D3:D11) -> 4 | E12: =SUM(E3:E11) -> 4 | F12: =SUM(F3:F11) -> 5 | G12: =SUM(G3:G11) -> 5 | H12: =SUM(H3:H11) -> 6 | I12: =SUM(I3:I11) -> 4 | ... K12: =SUM(K3:K11) -> 5 | L12: =SUM(B12:K12) -> 51 | M12: H'max= | N12: =LN(B16) -> 2.1972246
A16: всего технических приемов в группе: | B16: =COUNTA(A3:A11) -> 9
A19: Индекс вариативности на спортсмена | E19: =SUM(B12:K12)/10 -> 5.1
A20: вариативность техники в тати-вадза в группе 1 | B20: =B16/E19 -> 1.7647059
A31: Группа №2 (контрольная)
A32: Названия приемов | B32: Астапова К. | C32: Астапов М. | D32: Володин М. | E32: Гостев К. | F32: Кандеев А. | G32: Марушин Д. | H32: Марушин Т. | I32: Петиков В. | J32: Сафронов А. | K32: Янкин М. | L32: всего продемонстрировали отдельную технику:
A33: кеса-гатамэ | B33: 1 | C33: 1 | D33: 1 | F33: 1 | G33: 1 | H33: 1 | I33: 1 | J33: 1 | K33: 1 | L33: =SUM(B33:K33) -> 9
A34: ката-гатамэ | E34: 1 | K34: 1
A35: ёко-сихо-гатамэ (захват с ногой и рукой) | B35: 1 | C35: 1 | D35: 1 | F35: 1 | L35: =SUM(B35:K35) -> 4
A36: ёко-сихо-гатамэ (захват с рукой) | B36: 1 | D36: 1 | E36: 1 | H36: 1 | I36: 1 | J36: 1 | K36: 1 | L36: =SUM(B36:K36) -> 7
A37: татэ-сихо-гатамэ | B37: 1 | C37: 1 | F37: 1 | G37: 1 | H37: 1 | I37: 1 | J37: 1 | K37: 1 | L37: =SUM(B37:K37) -> 8
A38: кузурэ-кеса-гатамэ | B38: 1 | E38: 1 | H38: 1 | L38: =SUM(B38:K38) -> 3
A39: ёко-сихо-гатамэ (захват с рукой и головой) | G39: 1 | K39: 1 | L39: =SUM(B39:K39) -> 2
A40: ками-сихо-гатамэ | B40: 1 | C40: 1 | D40: 1 | K40: 1 | L40: =SUM(B40:K40) -> 4
A41: ёко-сихо-гатамэ (захват с ногой и головой) | E41: 1 | F41: 1 | G41: 1 | I41: 1 | J41: 1 | K41: 1 | L41: =SUM(B41:K41) -> 6
A42: уширо-кеса-гатамэ | C42: 1 | H42: 1 | K42: 1 | L42: =SUM(B42:K42) -> 3
A43: Всего различных приемов у спортсмена: | B43: =SUM(B33:B42) -> 6 | C43: =SUM(C33:C42) -> 5 | D43: =SUM(D33:D42) -> 4 | E43: =SUM(E33:E42) -> 4 | F43: =SUM(F33:F42) -> 4 | G43: =SUM(G33:G42) -> 4 | H43: =SUM(H33:H42) -> 5 | I43: =SUM(I33:I42) -> 4 | ... K43: =SUM(K33:K42) -> 8 | L43: =SUM(B43:K43) -> 48
A47: всего технических приемов в группе: | B47: =COUNTA(A33:A42) -> 10
A50: Индекс вариативности на спортсмена | E50: =SUM(B43:K43)/10 -> 4.8
A51: вариативность техники в тати-вадза в группе 2 | B51: =B47/E50 -> 2.0833333

Sheet эффективность
A1: Группа №1 (эксперимнентальная)
A2: № | B2: ФИО | C2: S - кол-во успешных попыток | D2: N - кол-во всех попыток | E2: E(эффективность)=S/N
A3: 1 | B3: Арутюнян Э. | C3: 4 | D3: 5 | E3: =C3/D3*100% -> 0.8
A4: 2 | B4: Корчагина А. | C4: 2 | D4: 4 | E4: =C4/D4*100% -> 0.5
A5: 3 | B5: Закоптелкова М. | C5: 2 | D5: 7 | E5: =C5/D5*100% -> 0.28571429
A6: 4 | B6: Голубинская А. | C6: 1 | D6: 9 | E6: =C6/D6*100% -> 0.11111111
A7: 5 | B7: Алиев А. | C7: 3 | D7: 6 | E7: =C7/D7*100% -> 0.5
A8: 6 | B8: Устинов | C8: 1 | D8: 6 | E8: =C8/D8*100% -> 0.16666667
A9: 7 | B9: Закоптелков С. | C9: 5 | D9: 11 | E9: =C9/D9*100% -> 0.45454545
A10: 8 | B10: Ефремов Е. | C10: 2 | D10: 10 | E10: =C10/D10*100% -> 0.2
A11: 9 | B11: Гейдарзаде У. | C11: 4 | D11: 8 | E11: =C11/D11*100% -> 0.5
A12: 10 | B12: Шубин И. | C12: 6 | D12: 8 | E12: =C12/D12*100% -> 0.75
D13: средняя Е: | E13: =AVERAGE(E3:E12) -> 0.42680375
A19: Группа №2(контрольная)
A20: № | B20: ФИО | C20: S - кол-во успешных попыток | D20: N - кол-во всех попыток | E20: E(эффективность)=S/N
A21: 1 | B21: Астапова К. | C21: 4 | D21: 6 | E21: =C21/D21*100% -> 0.66666667
A22: 2 | B22: Астапов М. | C22: 3 | D22: 4 | E22: =C22/D22*100% -> 0.75
A23: 3 | B23: Володин М. | C23: 3 | D23: 6 | E23: =C23/D23*100% -> 0.5
A24: 4 | B24: Гостев К. | C24: 2 | D24: 8 | E24: =C24/D24*100% -> 0.25
A25: 5 | B25: Кандеев А. | C25: 3 | D25: 8 | E25: =C25/D25*100% -> 0.375
A26: 6 | B26: Марушин Д. | C26: 1 | D26: 7 | E26: =C26/D26*100% -> 0.14285714
A27: 7 | B27: Марушин Т. | C27: 6 | D27: 12 | E27: =C27/D27*100% -> 0.5
A28: 8 | B28: Петиков В. | C28: 3 | D28: 11 | E28: =C28/D28*100% -> 0.27272727
A29: 9 | B29: Сафронов А. | C29: 0 | D29: 8 | E29: =C29/D29*100% -> 0
A30: 10 | B30: Янкин М. | C30: 4 | D30: 6 | E30: =C30/D30*100% -> 0.66666667
D31: средняя Е: | E31: =AVERAGE(E21:E30) -> 0.41239177

Sheet стабильность
A1: Группа №1 (эксперимнентальная)
A2: № | B2: ФИО | C2: количество бросков за первые 30 с (n) | D2: количество бросков за вторые 30 с | E2: количество бросков за третьи 30 с | F2: количество бросков за последние 30 с (N) | G2: Kст (коэф.стабильности) = N/n*100%
A3: 1 | B3: Арутюнян Э. | C3: 10 | D3: 10 | E3: 9 | F3: 9 | G3: =F3/C3 -> 0.9
A4: 2 | B4: Корчагина А. | C4: 9 | D4: 8 | E4: 9 | F4: 9 | G4: =F4/C4 -> 1
A5: 3 | B5: Закоптелкова М. | C5: 7 | D5: 5 | E5: 6 | F5: 5 | G5: =F5/C5 -> 0.71428571
A6: 4 | B6: Голубинская А. | C6: 4 | D6: 2 | E6: 2 | F6: 3 | G6: =F6/C6 -> 0.75
A7: 5 | B7: Алиев А. | C7: 9 | D7: 6 | E7: 6 | F7: 6 | G7: =F7/C7 -> 0.66666667
A8: 6 | B8: Устинов | C8: 6 | D8: 5 | E8: 4 | F8: 3 | G8: =F8/C8 -> 0.5
A9: 7 | B9: Закоптелков С. | C9: 8 | D9: 6 | E9: 6 | F9: 4 | G9: =F9/C9 -> 0.5
A10: 8 | B10: Ефремов Е. | C10: 7 | D10: 6 | E10: 5 | F10: 4 | G10: =F10/C10 -> 0.57142857
A11: 9 | B11: Гейдарзаде У. | C11: 7 | D11: 6 | E11: 5 | F11: 5 | G11: =F11/C11 -> 0.71428571
A12: 10 | B12: Шубин И. | C12: 13 | D12: 11 | E12: 10 | F12: 9 | G12: =F12/C12 -> 0.69230769
F13: Кст (среднее)= | G13: =AVERAGE(G3:G12) -> 0.70089744
A24: Группа №2 (контрольная)
A25: № | B25: ФИО | C25: количество бросков за первые 30 с (n) | D25: количество бросков за вторые 30 с | E25: количество бросков за третьи 30 с | F25: количество бросков за последние 30 с (N) | G25: Kст (коэф.стабильности) = N/n*100%
A26: 1 | B26: Астапова К. | C26: 7 | D26: 7 | E26: 6 | F26: 5 | G26: =F26/C26 -> 0.71428571
A27: 2 | B27: Астапов М. | C27: 4 | D27: 4 | E27: 3 | F27: 4 | G27: =F27/C27 -> 1
A28: 3 | B28: Володин М. | C28: 8 | D28: 9 | E28: 6 | F28: 4 | G28: =F28/C28 -> 0.5
A29: 4 | B29: Гостев К. | C29: 7 | D29: 4 | E29: 4 | F29: 3 | G29: =F29/C29 -> 0.42857143
A30: 5 | B30: Кандеев А. | C30: 9 | D30: 10 | E30: 6 | F30: 6 | G30: =F30/C30 -> 0.66666667
A31: 6 | B31: Марушин Д. | C31: 6 | D31: 6 | E31: 5 | F31: 3 | G31: =F31/C31 -> 0.5
A32: 7 | B32: Марушин Т. | C32: 8 | D32: 9 | E32: 6 | F32: 7 | G32: =F32/C32 -> 0.875
A33: 8 | B33: Петиков В. | C33: 7 | D33: 6 | E33: 5 | F33: 4 | G33: =F33/C33 -> 0.57142857
A34: 9 | B34: Сафронов А. | C34: 10 | D34: 9 | E34: 8 | F34: 6 | G34: =F34/C34 -> 0.6
A35: 10 | B35: Янкин М. | C35: 12 | D35: 11 | E35: 8 | F35: 7 | G35: =F35/C35 -> 0.58333333
F36: Кст (среднее)= | G36: =AVERAGE(G26:G35) -> 0.64392857
